{
 "cells": [
  {
   "cell_type": "code",
   "execution_count": 14,
   "id": "initial_id",
   "metadata": {
    "collapsed": true,
    "ExecuteTime": {
     "end_time": "2023-11-06T09:58:21.868778Z",
     "start_time": "2023-11-06T09:58:21.859919Z"
    }
   },
   "outputs": [],
   "source": [
    "import numpy as np\n",
    "import tensorflow as tf\n",
    "from tensorflow.keras import datasets, layers, models"
   ]
  },
  {
   "cell_type": "code",
   "execution_count": 15,
   "outputs": [],
   "source": [
    "# Load the data from the .npz file\n",
    "data = np.load('faces_embeddings_done_14classes.npz')\n",
    "x_train = data['arr_1']\n",
    "y_train = data['arr_0']"
   ],
   "metadata": {
    "collapsed": false,
    "ExecuteTime": {
     "end_time": "2023-11-06T09:58:22.655169Z",
     "start_time": "2023-11-06T09:58:22.621338Z"
    }
   },
   "id": "c861ef2ccbaebe91"
  },
  {
   "cell_type": "code",
   "execution_count": 16,
   "outputs": [],
   "source": [
    "# Convert the labels to one-hot encoded vectors\n",
    "y_train = tf.keras.utils.to_categorical(y_train, num_classes=14)"
   ],
   "metadata": {
    "collapsed": false,
    "ExecuteTime": {
     "end_time": "2023-11-06T09:58:22.980697Z",
     "start_time": "2023-11-06T09:58:22.957024Z"
    }
   },
   "id": "cfed9983f2bbdbe3"
  },
  {
   "cell_type": "code",
   "execution_count": 17,
   "outputs": [],
   "source": [
    "# Define the model\n",
    "model = models.Sequential()\n",
    "model.add(layers.Dense(64, activation='relu', input_shape=(512,)))\n",
    "model.add(layers.Dense(10, activation='softmax'))"
   ],
   "metadata": {
    "collapsed": false,
    "ExecuteTime": {
     "end_time": "2023-11-06T09:58:23.510423Z",
     "start_time": "2023-11-06T09:58:23.488988Z"
    }
   },
   "id": "f5c4a8c64ee01c64"
  },
  {
   "cell_type": "code",
   "execution_count": 18,
   "outputs": [],
   "source": [
    "# Compile the model\n",
    "model.compile(optimizer='adam',\n",
    "              loss='sparse_categorical_crossentropy',\n",
    "              metrics=['accuracy'])"
   ],
   "metadata": {
    "collapsed": false,
    "ExecuteTime": {
     "end_time": "2023-11-06T09:58:24.051492Z",
     "start_time": "2023-11-06T09:58:24.046123Z"
    }
   },
   "id": "cb9d402458a4129d"
  },
  {
   "cell_type": "code",
   "execution_count": 19,
   "outputs": [
    {
     "name": "stdout",
     "output_type": "stream",
     "text": [
      "Epoch 1/10\n"
     ]
    },
    {
     "ename": "ValueError",
     "evalue": "in user code:\n\n    File \"/Users/skull/PycharmProjects/Face Recognition System/venv/lib/python3.9/site-packages/keras/src/engine/training.py\", line 1338, in train_function  *\n        return step_function(self, iterator)\n    File \"/Users/skull/PycharmProjects/Face Recognition System/venv/lib/python3.9/site-packages/keras/src/engine/training.py\", line 1322, in step_function  **\n        outputs = model.distribute_strategy.run(run_step, args=(data,))\n    File \"/Users/skull/PycharmProjects/Face Recognition System/venv/lib/python3.9/site-packages/keras/src/engine/training.py\", line 1303, in run_step  **\n        outputs = model.train_step(data)\n    File \"/Users/skull/PycharmProjects/Face Recognition System/venv/lib/python3.9/site-packages/keras/src/engine/training.py\", line 1080, in train_step\n        y_pred = self(x, training=True)\n    File \"/Users/skull/PycharmProjects/Face Recognition System/venv/lib/python3.9/site-packages/keras/src/utils/traceback_utils.py\", line 70, in error_handler\n        raise e.with_traceback(filtered_tb) from None\n    File \"/Users/skull/PycharmProjects/Face Recognition System/venv/lib/python3.9/site-packages/keras/src/engine/input_spec.py\", line 253, in assert_input_compatibility\n        raise ValueError(\n\n    ValueError: Exception encountered when calling layer 'sequential_3' (type Sequential).\n    \n    Input 0 of layer \"dense_4\" is incompatible with the layer: expected min_ndim=2, found ndim=1. Full shape received: (None,)\n    \n    Call arguments received by layer 'sequential_3' (type Sequential):\n      • inputs=tf.Tensor(shape=(None,), dtype=string)\n      • training=True\n      • mask=None\n",
     "output_type": "error",
     "traceback": [
      "\u001B[0;31m---------------------------------------------------------------------------\u001B[0m",
      "\u001B[0;31mValueError\u001B[0m                                Traceback (most recent call last)",
      "Cell \u001B[0;32mIn[19], line 2\u001B[0m\n\u001B[1;32m      1\u001B[0m \u001B[38;5;66;03m# Train the model\u001B[39;00m\n\u001B[0;32m----> 2\u001B[0m \u001B[43mmodel\u001B[49m\u001B[38;5;241;43m.\u001B[39;49m\u001B[43mfit\u001B[49m\u001B[43m(\u001B[49m\u001B[43mx_train\u001B[49m\u001B[43m,\u001B[49m\u001B[43m \u001B[49m\u001B[43my_train\u001B[49m\u001B[43m,\u001B[49m\u001B[43m \u001B[49m\u001B[43mepochs\u001B[49m\u001B[38;5;241;43m=\u001B[39;49m\u001B[38;5;241;43m10\u001B[39;49m\u001B[43m)\u001B[49m\n",
      "File \u001B[0;32m~/PycharmProjects/Face Recognition System/venv/lib/python3.9/site-packages/keras/src/utils/traceback_utils.py:70\u001B[0m, in \u001B[0;36mfilter_traceback.<locals>.error_handler\u001B[0;34m(*args, **kwargs)\u001B[0m\n\u001B[1;32m     67\u001B[0m     filtered_tb \u001B[38;5;241m=\u001B[39m _process_traceback_frames(e\u001B[38;5;241m.\u001B[39m__traceback__)\n\u001B[1;32m     68\u001B[0m     \u001B[38;5;66;03m# To get the full stack trace, call:\u001B[39;00m\n\u001B[1;32m     69\u001B[0m     \u001B[38;5;66;03m# `tf.debugging.disable_traceback_filtering()`\u001B[39;00m\n\u001B[0;32m---> 70\u001B[0m     \u001B[38;5;28;01mraise\u001B[39;00m e\u001B[38;5;241m.\u001B[39mwith_traceback(filtered_tb) \u001B[38;5;28;01mfrom\u001B[39;00m \u001B[38;5;28;01mNone\u001B[39;00m\n\u001B[1;32m     71\u001B[0m \u001B[38;5;28;01mfinally\u001B[39;00m:\n\u001B[1;32m     72\u001B[0m     \u001B[38;5;28;01mdel\u001B[39;00m filtered_tb\n",
      "File \u001B[0;32m/var/folders/vw/4rypl92n2wb3py3wlk9sjt_c0000gn/T/__autograph_generated_filez0yz3cr5.py:15\u001B[0m, in \u001B[0;36mouter_factory.<locals>.inner_factory.<locals>.tf__train_function\u001B[0;34m(iterator)\u001B[0m\n\u001B[1;32m     13\u001B[0m \u001B[38;5;28;01mtry\u001B[39;00m:\n\u001B[1;32m     14\u001B[0m     do_return \u001B[38;5;241m=\u001B[39m \u001B[38;5;28;01mTrue\u001B[39;00m\n\u001B[0;32m---> 15\u001B[0m     retval_ \u001B[38;5;241m=\u001B[39m ag__\u001B[38;5;241m.\u001B[39mconverted_call(ag__\u001B[38;5;241m.\u001B[39mld(step_function), (ag__\u001B[38;5;241m.\u001B[39mld(\u001B[38;5;28mself\u001B[39m), ag__\u001B[38;5;241m.\u001B[39mld(iterator)), \u001B[38;5;28;01mNone\u001B[39;00m, fscope)\n\u001B[1;32m     16\u001B[0m \u001B[38;5;28;01mexcept\u001B[39;00m:\n\u001B[1;32m     17\u001B[0m     do_return \u001B[38;5;241m=\u001B[39m \u001B[38;5;28;01mFalse\u001B[39;00m\n",
      "\u001B[0;31mValueError\u001B[0m: in user code:\n\n    File \"/Users/skull/PycharmProjects/Face Recognition System/venv/lib/python3.9/site-packages/keras/src/engine/training.py\", line 1338, in train_function  *\n        return step_function(self, iterator)\n    File \"/Users/skull/PycharmProjects/Face Recognition System/venv/lib/python3.9/site-packages/keras/src/engine/training.py\", line 1322, in step_function  **\n        outputs = model.distribute_strategy.run(run_step, args=(data,))\n    File \"/Users/skull/PycharmProjects/Face Recognition System/venv/lib/python3.9/site-packages/keras/src/engine/training.py\", line 1303, in run_step  **\n        outputs = model.train_step(data)\n    File \"/Users/skull/PycharmProjects/Face Recognition System/venv/lib/python3.9/site-packages/keras/src/engine/training.py\", line 1080, in train_step\n        y_pred = self(x, training=True)\n    File \"/Users/skull/PycharmProjects/Face Recognition System/venv/lib/python3.9/site-packages/keras/src/utils/traceback_utils.py\", line 70, in error_handler\n        raise e.with_traceback(filtered_tb) from None\n    File \"/Users/skull/PycharmProjects/Face Recognition System/venv/lib/python3.9/site-packages/keras/src/engine/input_spec.py\", line 253, in assert_input_compatibility\n        raise ValueError(\n\n    ValueError: Exception encountered when calling layer 'sequential_3' (type Sequential).\n    \n    Input 0 of layer \"dense_4\" is incompatible with the layer: expected min_ndim=2, found ndim=1. Full shape received: (None,)\n    \n    Call arguments received by layer 'sequential_3' (type Sequential):\n      • inputs=tf.Tensor(shape=(None,), dtype=string)\n      • training=True\n      • mask=None\n"
     ]
    }
   ],
   "source": [
    "# Train the model\n",
    "model.fit(x_train, y_train, epochs=10)"
   ],
   "metadata": {
    "collapsed": false,
    "ExecuteTime": {
     "end_time": "2023-11-06T09:58:24.756028Z",
     "start_time": "2023-11-06T09:58:24.645575Z"
    }
   },
   "id": "ea7bba99cc8cd2cc"
  },
  {
   "cell_type": "code",
   "execution_count": 24,
   "outputs": [
    {
     "name": "stdout",
     "output_type": "stream",
     "text": [
      "Epoch 1/10\n"
     ]
    },
    {
     "ename": "ValueError",
     "evalue": "in user code:\n\n    File \"/Users/skull/PycharmProjects/Face Recognition System/venv/lib/python3.9/site-packages/keras/src/engine/training.py\", line 1338, in train_function  *\n        return step_function(self, iterator)\n    File \"/Users/skull/PycharmProjects/Face Recognition System/venv/lib/python3.9/site-packages/keras/src/engine/training.py\", line 1322, in step_function  **\n        outputs = model.distribute_strategy.run(run_step, args=(data,))\n    File \"/Users/skull/PycharmProjects/Face Recognition System/venv/lib/python3.9/site-packages/keras/src/engine/training.py\", line 1303, in run_step  **\n        outputs = model.train_step(data)\n    File \"/Users/skull/PycharmProjects/Face Recognition System/venv/lib/python3.9/site-packages/keras/src/engine/training.py\", line 1080, in train_step\n        y_pred = self(x, training=True)\n    File \"/Users/skull/PycharmProjects/Face Recognition System/venv/lib/python3.9/site-packages/keras/src/utils/traceback_utils.py\", line 70, in error_handler\n        raise e.with_traceback(filtered_tb) from None\n    File \"/Users/skull/PycharmProjects/Face Recognition System/venv/lib/python3.9/site-packages/keras/src/engine/input_spec.py\", line 253, in assert_input_compatibility\n        raise ValueError(\n\n    ValueError: Exception encountered when calling layer 'sequential_7' (type Sequential).\n    \n    Input 0 of layer \"dense_15\" is incompatible with the layer: expected min_ndim=2, found ndim=1. Full shape received: (None,)\n    \n    Call arguments received by layer 'sequential_7' (type Sequential):\n      • inputs=tf.Tensor(shape=(None,), dtype=string)\n      • training=True\n      • mask=None\n",
     "output_type": "error",
     "traceback": [
      "\u001B[0;31m---------------------------------------------------------------------------\u001B[0m",
      "\u001B[0;31mValueError\u001B[0m                                Traceback (most recent call last)",
      "Cell \u001B[0;32mIn[24], line 26\u001B[0m\n\u001B[1;32m     21\u001B[0m model\u001B[38;5;241m.\u001B[39mcompile(optimizer\u001B[38;5;241m=\u001B[39m\u001B[38;5;124m'\u001B[39m\u001B[38;5;124madam\u001B[39m\u001B[38;5;124m'\u001B[39m,\n\u001B[1;32m     22\u001B[0m               loss\u001B[38;5;241m=\u001B[39m\u001B[38;5;124m'\u001B[39m\u001B[38;5;124mcategorical_crossentropy\u001B[39m\u001B[38;5;124m'\u001B[39m,\n\u001B[1;32m     23\u001B[0m               metrics\u001B[38;5;241m=\u001B[39m[\u001B[38;5;124m'\u001B[39m\u001B[38;5;124maccuracy\u001B[39m\u001B[38;5;124m'\u001B[39m])\n\u001B[1;32m     25\u001B[0m \u001B[38;5;66;03m# Train the model\u001B[39;00m\n\u001B[0;32m---> 26\u001B[0m \u001B[43mmodel\u001B[49m\u001B[38;5;241;43m.\u001B[39;49m\u001B[43mfit\u001B[49m\u001B[43m(\u001B[49m\u001B[43mx_train\u001B[49m\u001B[43m,\u001B[49m\u001B[43m \u001B[49m\u001B[43my_train\u001B[49m\u001B[43m,\u001B[49m\u001B[43m \u001B[49m\u001B[43mepochs\u001B[49m\u001B[38;5;241;43m=\u001B[39;49m\u001B[38;5;241;43m10\u001B[39;49m\u001B[43m)\u001B[49m\n",
      "File \u001B[0;32m~/PycharmProjects/Face Recognition System/venv/lib/python3.9/site-packages/keras/src/utils/traceback_utils.py:70\u001B[0m, in \u001B[0;36mfilter_traceback.<locals>.error_handler\u001B[0;34m(*args, **kwargs)\u001B[0m\n\u001B[1;32m     67\u001B[0m     filtered_tb \u001B[38;5;241m=\u001B[39m _process_traceback_frames(e\u001B[38;5;241m.\u001B[39m__traceback__)\n\u001B[1;32m     68\u001B[0m     \u001B[38;5;66;03m# To get the full stack trace, call:\u001B[39;00m\n\u001B[1;32m     69\u001B[0m     \u001B[38;5;66;03m# `tf.debugging.disable_traceback_filtering()`\u001B[39;00m\n\u001B[0;32m---> 70\u001B[0m     \u001B[38;5;28;01mraise\u001B[39;00m e\u001B[38;5;241m.\u001B[39mwith_traceback(filtered_tb) \u001B[38;5;28;01mfrom\u001B[39;00m \u001B[38;5;28;01mNone\u001B[39;00m\n\u001B[1;32m     71\u001B[0m \u001B[38;5;28;01mfinally\u001B[39;00m:\n\u001B[1;32m     72\u001B[0m     \u001B[38;5;28;01mdel\u001B[39;00m filtered_tb\n",
      "File \u001B[0;32m/var/folders/vw/4rypl92n2wb3py3wlk9sjt_c0000gn/T/__autograph_generated_filez0yz3cr5.py:15\u001B[0m, in \u001B[0;36mouter_factory.<locals>.inner_factory.<locals>.tf__train_function\u001B[0;34m(iterator)\u001B[0m\n\u001B[1;32m     13\u001B[0m \u001B[38;5;28;01mtry\u001B[39;00m:\n\u001B[1;32m     14\u001B[0m     do_return \u001B[38;5;241m=\u001B[39m \u001B[38;5;28;01mTrue\u001B[39;00m\n\u001B[0;32m---> 15\u001B[0m     retval_ \u001B[38;5;241m=\u001B[39m ag__\u001B[38;5;241m.\u001B[39mconverted_call(ag__\u001B[38;5;241m.\u001B[39mld(step_function), (ag__\u001B[38;5;241m.\u001B[39mld(\u001B[38;5;28mself\u001B[39m), ag__\u001B[38;5;241m.\u001B[39mld(iterator)), \u001B[38;5;28;01mNone\u001B[39;00m, fscope)\n\u001B[1;32m     16\u001B[0m \u001B[38;5;28;01mexcept\u001B[39;00m:\n\u001B[1;32m     17\u001B[0m     do_return \u001B[38;5;241m=\u001B[39m \u001B[38;5;28;01mFalse\u001B[39;00m\n",
      "\u001B[0;31mValueError\u001B[0m: in user code:\n\n    File \"/Users/skull/PycharmProjects/Face Recognition System/venv/lib/python3.9/site-packages/keras/src/engine/training.py\", line 1338, in train_function  *\n        return step_function(self, iterator)\n    File \"/Users/skull/PycharmProjects/Face Recognition System/venv/lib/python3.9/site-packages/keras/src/engine/training.py\", line 1322, in step_function  **\n        outputs = model.distribute_strategy.run(run_step, args=(data,))\n    File \"/Users/skull/PycharmProjects/Face Recognition System/venv/lib/python3.9/site-packages/keras/src/engine/training.py\", line 1303, in run_step  **\n        outputs = model.train_step(data)\n    File \"/Users/skull/PycharmProjects/Face Recognition System/venv/lib/python3.9/site-packages/keras/src/engine/training.py\", line 1080, in train_step\n        y_pred = self(x, training=True)\n    File \"/Users/skull/PycharmProjects/Face Recognition System/venv/lib/python3.9/site-packages/keras/src/utils/traceback_utils.py\", line 70, in error_handler\n        raise e.with_traceback(filtered_tb) from None\n    File \"/Users/skull/PycharmProjects/Face Recognition System/venv/lib/python3.9/site-packages/keras/src/engine/input_spec.py\", line 253, in assert_input_compatibility\n        raise ValueError(\n\n    ValueError: Exception encountered when calling layer 'sequential_7' (type Sequential).\n    \n    Input 0 of layer \"dense_15\" is incompatible with the layer: expected min_ndim=2, found ndim=1. Full shape received: (None,)\n    \n    Call arguments received by layer 'sequential_7' (type Sequential):\n      • inputs=tf.Tensor(shape=(None,), dtype=string)\n      • training=True\n      • mask=None\n"
     ]
    }
   ],
   "source": [
    "import tensorflow as tf\n",
    "from tensorflow import keras\n",
    "from tensorflow.keras import layers\n",
    "\n",
    "# Load the embedded face representations and labels from the .npz file\n",
    "data = np.load('faces_embeddings_done_14classes.npz')\n",
    "x_train = data['arr_1']\n",
    "y_train = data['arr_0']\n",
    "\n",
    "# Convert the labels to one-hot encoded vectors\n",
    "y_train = tf.keras.utils.to_categorical(y_train, num_classes=14)\n",
    "\n",
    "# Define the deep learning model\n",
    "model = keras.Sequential([\n",
    "    layers.Dense(256, activation='relu', input_shape=(512,)),\n",
    "    layers.Dense(128, activation='relu'),\n",
    "    layers.Dense(14, activation='softmax')\n",
    "])\n",
    "\n",
    "# Compile the model\n",
    "model.compile(optimizer='adam',\n",
    "              loss='categorical_crossentropy',\n",
    "              metrics=['accuracy'])\n",
    "\n",
    "# Train the model\n",
    "model.fit(x_train, y_train, epochs=10)\n"
   ],
   "metadata": {
    "collapsed": false,
    "ExecuteTime": {
     "end_time": "2023-11-06T09:59:27.314567Z",
     "start_time": "2023-11-06T09:59:27.104437Z"
    }
   },
   "id": "5654405bd5ba5535"
  },
  {
   "cell_type": "code",
   "execution_count": null,
   "outputs": [],
   "source": [],
   "metadata": {
    "collapsed": false
   },
   "id": "2f80c997d4ddaf27"
  }
 ],
 "metadata": {
  "kernelspec": {
   "display_name": "Python 3",
   "language": "python",
   "name": "python3"
  },
  "language_info": {
   "codemirror_mode": {
    "name": "ipython",
    "version": 2
   },
   "file_extension": ".py",
   "mimetype": "text/x-python",
   "name": "python",
   "nbconvert_exporter": "python",
   "pygments_lexer": "ipython2",
   "version": "2.7.6"
  }
 },
 "nbformat": 4,
 "nbformat_minor": 5
}
